# 异常处理基础以及异步异常处理

```js
try{
	throw new Error("我把错误爆出来")
}catch(e){
	console.log("我把错误吃掉了")
}
```

```js
function f1(){
    try{
        f2()
    }catch(error){
        console.log("f1抛出错误")
        throw error
    }
}

function f2(){
    try{
        f3()
    }catch(error){
        console.log("f2抛出错误")
        throw error
    }
}

function f3(){
    try{
        console.log(1/a)
    }catch(error){
        console.log("f3抛出错误")
        throw error
    }
}

f1()
```

```js
try{
	asyError()
}catch(e){
	console.log("我把错误吃掉了")
}
function asyError(){
	setTimeout(()=>{
		throw new Error("我是无法被捕获的异步函数！")
	},1000)
}
```

![1559320056221](C:\Users\Administrator\AppData\Roaming\Typora\typora-user-images\1559320056221.png)

如果我们promise抛出了一个异常，但是外部却没有处理，那就会报错（unhandled promise）

```js
async function fun2(){
		try{
			fun3()
			//这里抛出的异常就没有被处理（await可以直接捕获或者抛出reject或者resolve的值。）
		}catch(e){
			console.log(e)
		}
}

function asye(){
	return new Promise(reject=>{
		setTimeout(()=>{
			reject("error")
		})
	})
}
fun2()
```

```js
async function tryer(){
        let a  = await proTimer()       
        console.log(a)  //1
        let b = await asyTimer()
        console.log(b)  //undefined
        let c = await consol()
        console.log(c)  //1
}

function proTimer(){
    return new Promise(resolve=>{
        setTimeout(function(){
            resolve(1)
        })
    })
}

async function asyTimer(){
    setTimeout(function(){
        return 1
    })
}

async function consol(){
    return 1
}

tryer()
```

