# Error

通过**Error**的构造器可以创建一个错误对象。当运行时错误产生时，Error的实例对象会被抛出。Error对象也可用于用户自定义的异常的基础对象。下面列出了各种内建的标准错误类型。

## 语法

```js
new Error([message[, fileName[,lineNumber]]])
```

**参数：**

`message`：可选。人类可阅读的错误描述信息。

`fileName `：可选。被创建的Error对象的fileName属性值。默认是调用Error构造器代码所在的文件 的名字。

`lineNumber `：可选。被创建的Error对象的lineNumber属性值。默认是调用Error构造器代码所在的文件的行号。

**描述：**

当代码运行时的发生错误，会创建新的`Error` 对象，并将其抛出。

当像函数一样使用 `Error` 时 -- 如果没有 [`new`](https://developer.mozilla.org/zh-CN/docs/Web/JavaScript/Reference/Operators/new)，它将返回一个 `Error` 对象。所以， 仅仅调用 `Error` 产生的结果与通过`new` 关键字构造 `Error` 对象生成的结果相同。 

```js
// this:
const x = Error('I was created using a function call!');
// has the same functionality as this:
const y = new Error('I was constructed via the "new" keyword!');
```

## `Error` 子类型

除了通用的Error构造函数外，JavaScript还有6个其他类型的错误构造函数。

**[`RangeError`](https://developer.mozilla.org/zh-CN/docs/Web/JavaScript/Reference/Global_Objects/RangeError)**：创建一个error实例，表示错误的原因：数值变量或参数超出其有效范围。

```js
let str = "dsadsadasdasdas"; 
while (true) { str += str }
// Uncaught RangeError: Invalid string length

function foo() {foo()}; foo();
// Uncaught RangeError: Maximum call stack size exceeded
```

**[`ReferenceError`](https://developer.mozilla.org/zh-CN/docs/Web/JavaScript/Reference/Global_Objects/ReferenceError)**：创建一个error实例，表示错误的原因：无效引用。

```js
c
// Uncaught ReferenceError: c is not defined

d; let d
// Uncaught ReferenceError: d is not defined
```

**[`SyntaxError`](https://developer.mozilla.org/zh-CN/docs/Web/JavaScript/Reference/Global_Objects/SyntaxError)**：创建一个error实例，表示错误的原因：[`eval()`](https://developer.mozilla.org/zh-CN/docs/Web/JavaScript/Reference/Global_Objects/eval)在解析代码的过程中发生的语法错误。

```js
!=!
// Uncaught SyntaxError: Unexpected token '!='
  
const e
// Uncaught SyntaxError: Missing initializer in const declaration

const e = 1
const e = 1
// Uncaught SyntaxError: Identifier 'e' has already been declared
```

**[`TypeError`](https://developer.mozilla.org/zh-CN/docs/Web/JavaScript/Reference/Global_Objects/TypeError)**：创建一个error实例，表示错误的原因：变量或参数不属于有效类型。

```js
let a; 
a();
// Uncaught TypeError: a is not a function

let a; a.c
// Uncaught TypeError: Cannot read property 'c' of undefined
```

**[`InternalError`](https://developer.mozilla.org/zh-CN/docs/Web/JavaScript/Reference/Global_Objects/InternalError)** ：创建一个代表Javascript引擎内部错误的异常抛出的实例。 如: "递归太多".

**[`URIError`](https://developer.mozilla.org/zh-CN/docs/Web/JavaScript/Reference/Global_Objects/URIError)**：创建一个error实例，表示错误的原因：给 [`encodeURI()`](https://developer.mozilla.org/zh-CN/docs/Web/JavaScript/Reference/Global_Objects/encodeURI)或 [`decodeURl()`](https://developer.mozilla.org/zh-CN/docs/Web/JavaScript/Reference/Global_Objects/decodeURI)传递的参数无效。

**[`EvalError`](https://developer.mozilla.org/zh-CN/docs/Web/JavaScript/Reference/Global_Objects/EvalError)**：创建一个error实例，表示错误的原因：与 [`eval()`](https://developer.mozilla.org/zh-CN/docs/Web/JavaScript/Reference/Global_Objects/eval) 有关。

## `Error.prototype `原型属性

`Error.prototype.constructor`：实例原型的构造函数。

[`Error.prototype.message`](https://developer.mozilla.org/zh-CN/docs/Web/JavaScript/Reference/Global_Objects/Error/message)：错误信息。

[`Error.prototype.name`](https://developer.mozilla.org/zh-CN/docs/Web/JavaScript/Reference/Global_Objects/Error/name)：错误名。

------

比如说下面因为栈溢出而爆的`RangeError`，属性`message`表示错误信息，`stack`表示错误位置（浏览器私有），`name`表示错误类型（构造函数名）

```js
function foo() {foo()}
try {
    foo()
} catch(err) {
  console.log(err.toString())
}

// message: "Maximum call stack size exceeded"
// stack: "RangeError: Maximum call stack size exceeded↵    at foo (<anonymous>:1:17)↵    at foo 	    				(<anonymous>:1:17)↵    at foo (<anonymous>:1:17)↵"
// __proto__: Error
  // constructor: ƒ RangeError()
  // message: ""
  // name: "RangeError"
```

##  `Error.prototype `原型方法

[`Error.prototype.toSource()`](https://developer.mozilla.org/zh-CN/docs/Web/JavaScript/Reference/Global_Objects/Error/toSource) ：返回一个包含特定 [`Error`](https://developer.mozilla.org/zh-CN/docs/Web/JavaScript/Reference/Global_Objects/Error) 对象的源代码字符串，你可以用该值新建一个新的对象。

[`Error.prototype.toString()`](https://developer.mozilla.org/zh-CN/docs/Web/JavaScript/Reference/Global_Objects/Error/toString)：返回一个表示该对象的字符串。

------

`toString`方法返回的是 `Error.prototype.name + err.message`：

```js
function foo() {foo()}
try {
    foo()
} catch(err) {
  console.log(err.toString())
}
// RangeError: Maximum call stack size exceeded
```

## 异步异常处理

`try...catch...`块中异步执行的语句产生的错误是不会被捕获的，这个行为和`async`中的异步错误类似，解决方案也大体相同，就是用` async Function `包裹并且使用` await `等待执行，`await`表达式会将错误抛出。

这里我们对执行的语句是不是异步没有要求，因为`await`并不要求求值的语句一定是异步的。

```js
const catchError = async(ctx,next)=>{
        try{
            await next()
        }catch(error){
          	// do something...
        }
}
```

## 自定义错误类型

自定义错误类型可以通过Error进行继承，根据业务场景定义自己的错误类型和属性，下面是一个自定义的服务器错误类：

```js
class HttpException extends Error{
    constructor(msg = "服务器异常",errorCode = 10000, code = 500){
        super()
        this.errCode = errorCode
        this.code = code
        this.msg = msg
    }
}

class Notfound extends HttpException {
    constructor(msg,errorCode){
       super()
       this.code = 404
       this.msg = msg||'404 Not Found'
       this.errorCode = errorCode
    }
}
```

还有它的全局处理函数：

```js
const catchError = async(ctx,next)=>{
        try{
            await next()
        }catch(error){
            const isDev = global.configs.environment === 'dev'

            const isHttpException = error instanceof global.errs.HttpException
            if(isDev && !isHttpException){			// 不是服务器特有错误就是基本错误类型，直接抛出。(测试环境)
                throw error
            }
            if(typeof error.msg == "object"){
                error.msg = error.msg[0]
            }
            if(isHttpException){
                ctx.body = {
                    msg : error.msg,
                    errorCode : error.errCode,
                    requestUrl: `${ctx.method} ${ctx.path}` 
                }
                ctx.status = error.code
            }else{
                ctx.body = {
                    msg : "对不起，我们错了。",
                    errorCode : 9999,
                    requestUrl: `${ctx.method} ${ctx.path}` 
                }
                ctx.status = 500
            }
        }
}

```

